Workbook

Sheet Resumo
B2: Controle Financeiro · Resumo
B3: Clínica Sensi · Orçado x Realizado por grupo do orçamento
B5: Orçamento total (obra + ambientação) | C5: =SUMIFS('Orçado x Realizado'!$H$8:$H$98,'Orçado x Realizado'!$C$8:$C$98,1) -> 271962.96
B6: Realizado até o momento | C6: =SUM(Lançamentos!$O$7:$O$200) -> 7071.52
B7: Saldo do orçamento | C7: =C5-C6 -> 264891.44
B8: % executado | C8: =IF(C5=0,0,C6/C5) -> 0.026001776
B10: Grupo do orçamento | C10: Orçado (R$) | D10: Realizado (R$) | E10: Saldo (R$) | F10: % executado | G10: % do orçamento total
B11: 001.01 · Despesas indiretas | C11: =SUMIFS('Orçado x Realizado'!$H$8:$H$98,'Orçado x Realizado'!$B$8:$B$98,"001.01",'Orçado x Realizado'!$C$8:$C$98,2) -> 24985.62 | D11: =SUMIF(Lançamentos!$F$7:$F$200,"001.01*",Lançamentos!$O$7:$O$200) -> 0 | E11: =C11-D11 -> 24985.62 | F11: =IF(C11=0,0,D11/C11) -> 0 | G11: =IF($C$5=0,0,C11/$C$5) -> 0.091871409
B12: 001.02 · Serviços preliminares | C12: =SUMIFS('Orçado x Realizado'!$H$8:$H$98,'Orçado x Realizado'!$B$8:$B$98,"001.02",'Orçado x Realizado'!$C$8:$C$98,2) -> 8695.5596 | D12: =SUMIF(Lançamentos!$F$7:$F$200,"001.02*",Lançamentos!$O$7:$O$200) -> 0 | E12: =C12-D12 -> 8695.5596 | F12: =IF(C12=0,0,D12/C12) -> 0 | G12: =IF($C$5=0,0,C12/$C$5) -> 0.031973324
B13: 001.03 · Paredes e paineis | C13: =SUMIFS('Orçado x Realizado'!$H$8:$H$98,'Orçado x Realizado'!$B$8:$B$98,"001.03",'Orçado x Realizado'!$C$8:$C$98,2) -> 10849 | D13: =SUMIF(Lançamentos!$F$7:$F$200,"001.03*",Lançamentos!$O$7:$O$200) -> 0 | E13: =C13-D13 -> 10849 | F13: =IF(C13=0,0,D13/C13) -> 0 | G13: =IF($C$5=0,0,C13/$C$5) -> 0.039891462
B14: 001.04 · Forro de gesso | C14: =SUMIFS('Orçado x Realizado'!$H$8:$H$98,'Orçado x Realizado'!$B$8:$B$98,"001.04",'Orçado x Realizado'!$C$8:$C$98,2) -> 3420 | D14: =SUMIF(Lançamentos!$F$7:$F$200,"001.04*",Lançamentos!$O$7:$O$200) -> 0 | E14: =C14-D14 -> 3420 | F14: =IF(C14=0,0,D14/C14) -> 0 | G14: =IF($C$5=0,0,C14/$C$5) -> 0.012575242
B15: 001.05 · Esquadrias | C15: =SUMIFS('Orçado x Realizado'!$H$8:$H$98,'Orçado x Realizado'!$B$8:$B$98,"001.05",'Orçado x Realizado'!$C$8:$C$98,2) -> 6470 | D15: =SUMIF(Lançamentos!$F$7:$F$200,"001.05*",Lançamentos!$O$7:$O$200) -> 0 | E15: =C15-D15 -> 6470 | F15: =IF(C15=0,0,D15/C15) -> 0 | G15: =IF($C$5=0,0,C15/$C$5) -> 0.023790005
B16: 001.06 · Revestimentos | C16: =SUMIFS('Orçado x Realizado'!$H$8:$H$98,'Orçado x Realizado'!$B$8:$B$98,"001.06",'Orçado x Realizado'!$C$8:$C$98,2) -> 24342.736 | D16: =SUMIF(Lançamentos!$F$7:$F$200,"001.06*",Lançamentos!$O$7:$O$200) -> 2660.36 | E16: =C16-D16 -> 21682.376 | F16: =IF(C16=0,0,D16/C16) -> 0.10928763 | G16: =IF($C$5=0,0,C16/$C$5) -> 0.089507544
B17: 001.07 · Pintura | C17: =SUMIFS('Orçado x Realizado'!$H$8:$H$98,'Orçado x Realizado'!$B$8:$B$98,"001.07",'Orçado x Realizado'!$C$8:$C$98,2) -> 18185.804 | D17: =SUMIF(Lançamentos!$F$7:$F$200,"001.07*",Lançamentos!$O$7:$O$200) -> 0 | E17: =C17-D17 -> 18185.804 | F17: =IF(C17=0,0,D17/C17) -> 0 | G17: =IF($C$5=0,0,C17/$C$5) -> 0.066868679
B18: 001.08 · Pedras, louças e metais | C18: =SUMIFS('Orçado x Realizado'!$H$8:$H$98,'Orçado x Realizado'!$B$8:$B$98,"001.08",'Orçado x Realizado'!$C$8:$C$98,2) -> 12515.077 | D18: =SUMIF(Lançamentos!$F$7:$F$200,"001.08*",Lançamentos!$O$7:$O$200) -> 0 | E18: =C18-D18 -> 12515.077 | F18: =IF(C18=0,0,D18/C18) -> 0 | G18: =IF($C$5=0,0,C18/$C$5) -> 0.046017581
B19: 001.09 · Instalações | C19: =SUMIFS('Orçado x Realizado'!$H$8:$H$98,'Orçado x Realizado'!$B$8:$B$98,"001.09",'Orçado x Realizado'!$C$8:$C$98,2) -> 32986.26 | D19: =SUMIF(Lançamentos!$F$7:$F$200,"001.09*",Lançamentos!$O$7:$O$200) -> 4411.16 | E19: =C19-D19 -> 28575.1 | F19: =IF(C19=0,0,D19/C19) -> 0.13372719 | G19: =IF($C$5=0,0,C19/$C$5) -> 0.12128953
B20: 001.10 · Limpeza | C20: =SUMIFS('Orçado x Realizado'!$H$8:$H$98,'Orçado x Realizado'!$B$8:$B$98,"001.10",'Orçado x Realizado'!$C$8:$C$98,2) -> 1498.34 | D20: =SUMIF(Lançamentos!$F$7:$F$200,"001.10*",Lançamentos!$O$7:$O$200) -> 0 | E20: =C20-D20 -> 1498.34 | F20: =IF(C20=0,0,D20/C20) -> 0 | G20: =IF($C$5=0,0,C20/$C$5) -> 0.0055093533
B21: 002.01 · Ambientação | C21: =SUMIFS('Orçado x Realizado'!$H$8:$H$98,'Orçado x Realizado'!$B$8:$B$98,"002.01",'Orçado x Realizado'!$C$8:$C$98,2) -> 128014.56 | D21: =SUMIF(Lançamentos!$F$7:$F$200,"002.01*",Lançamentos!$O$7:$O$200) -> 0 | E21: =C21-D21 -> 128014.56 | F21: =IF(C21=0,0,D21/C21) -> 0 | G21: =IF($C$5=0,0,C21/$C$5) -> 0.47070587
B22: TOTAL | C22: =SUM(C11:C21) -> 271962.96 | D22: =SUM(D11:D21) -> 7071.52 | E22: =C22-D22 -> 264891.44 | F22: =IF(C22=0,0,D22/C22) -> 0.026001776 | G22: =SUM(G11:G21) -> 1
B24: Por centro de custo (nome livre informado nos lançamentos)
B25: Centro de custo | C25: Qtd. lançamentos | D25: Valor (R$)
B26: Instalações Frigorígenas | C26: =COUNTIF(Lançamentos!$E$7:$E$200,B26) -> 1 | D26: =SUMIF(Lançamentos!$E$7:$E$200,B26,Lançamentos!$O$7:$O$200) -> 4411.16
B27: Revestimento Cerâmico | C27: =COUNTIF(Lançamentos!$E$7:$E$200,B27) -> 1 | D27: =SUMIF(Lançamentos!$E$7:$E$200,B27,Lançamentos!$O$7:$O$200) -> 2660.36
B28: TOTAL | C28: =SUM(C26:C27) -> 2 | D28: =SUM(D26:D27) -> 7071.52
B30: Conferência: total realizado = soma dos lançamentos | D30: =IF(ROUND(D22-C6,2)=0,"OK","REVISAR: há lançamentos sem código EAP ou com código inválido") -> OK

Sheet Orçado x Realizado
B2: Orçado x Realizado · EAP Clínica Sensi
B3: Fonte do orçado: 'Clínica Sense - Orçamento Executivo.xlsm', aba EAP (proposta set/2026, BDI 0% e impostos 0%). Realizado: soma dos Lançamentos vinculados ao código (inclui subníveis).
B4: Níveis 1 a 3 somam automaticamente os itens de nível 4. Use os botões de agrupamento (+/−) à esquerda para recolher os itens.
B7: Código | C7: Nível | D7: Descrição | E7: Und | F7: Quant. | G7: Preço unit. (R$) | H7: Orçado (R$) | I7: Realizado (R$) | J7: Saldo (R$) | K7: % executado
B8: 001 | C8: 1 | D8: OBRA | H8: =SUMIFS($H$8:$H$98,$B$8:$B$98,B8&"*",$C$8:$C$98,4) -> 143948.4 | I8: =SUMIF(Lançamentos!$F$7:$F$200,B8&"*",Lançamentos!$O$7:$O$200) -> 7071.52 | J8: =H8-I8 -> 136876.88 | K8: =IF(H8=0,0,I8/H8) -> 0.049125382
B9: 001.01 | C9: 2 | D9: DESPESAS INDIRETAS | H9: =SUMIFS($H$8:$H$98,$B$8:$B$98,B9&"*",$C$8:$C$98,4) -> 24985.62 | I9: =SUMIF(Lançamentos!$F$7:$F$200,B9&"*",Lançamentos!$O$7:$O$200) -> 0 | J9: =H9-I9 -> 24985.62 | K9: =IF(H9=0,0,I9/H9) -> 0
B10: 001.01.01 | C10: 3 | D10: DESPESAS MENSAIS | H10: =SUMIFS($H$8:$H$98,$B$8:$B$98,B10&"*",$C$8:$C$98,4) -> 3185.62 | I10: =SUMIF(Lançamentos!$F$7:$F$200,B10&"*",Lançamentos!$O$7:$O$200) -> 0 | J10: =H10-I10 -> 3185.62 | K10: =IF(H10=0,0,I10/H10) -> 0
B11: 001.01.01.01 | C11: 4 | D11: ART | E11: VB | F11: 1 | G11: 200 | H11: 200 | I11: =SUMIF(Lançamentos!$F$7:$F$200,B11&"*",Lançamentos!$O$7:$O$200) -> 0 | J11: =H11-I11 -> 200 | K11: =IF(H11=0,0,I11/H11) -> 0
B12: 001.01.01.02 | C12: 4 | D12: CUSTOS COM CANTEIRO DE OBRAS | E12: OE | F12: 1 | G12: 985.62 | H12: 985.62 | I12: =SUMIF(Lançamentos!$F$7:$F$200,B12&"*",Lançamentos!$O$7:$O$200) -> 0 | J12: =H12-I12 -> 985.62 | K12: =IF(H12=0,0,I12/H12) -> 0
B13: 001.01.01.03 | C13: 4 | D13: MOBILIZAÇÃO, DESMOBILIZAÇÃO E FRETES DA OBRA | E13: VB | F13: 1 | G13: 2000 | H13: 2000 | I13: =SUMIF(Lançamentos!$F$7:$F$200,B13&"*",Lançamentos!$O$7:$O$200) -> 0 | J13: =H13-I13 -> 2000 | K13: =IF(H13=0,0,I13/H13) -> 0
B14: 001.01.02 | C14: 3 | D14: EQUIPE ADMININSTRATIVA | H14: =SUMIFS($H$8:$H$98,$B$8:$B$98,B14&"*",$C$8:$C$98,4) -> 17400 | I14: =SUMIF(Lançamentos!$F$7:$F$200,B14&"*",Lançamentos!$O$7:$O$200) -> 0 | J14: =H14-I14 -> 17400 | K14: =IF(H14=0,0,I14/H14) -> 0
B15: 001.01.02.01 | C15: 4 | D15: EQUIPE ADMINISTRATIVA | E15: OE | F15: 3 | G15: 5800 | H15: 17400 | I15: =SUMIF(Lançamentos!$F$7:$F$200,B15&"*",Lançamentos!$O$7:$O$200) -> 0 | J15: =H15-I15 -> 17400 | K15: =IF(H15=0,0,I15/H15) -> 0
B16: 001.01.03 | C16: 3 | D16: LOCAÇÃO DE EQUIPAMENTOS | H16: =SUMIFS($H$8:$H$98,$B$8:$B$98,B16&"*",$C$8:$C$98,4) -> 2400 | I16: =SUMIF(Lançamentos!$F$7:$F$200,B16&"*",Lançamentos!$O$7:$O$200) -> 0 | J16: =H16-I16 -> 2400 | K16: =IF(H16=0,0,I16/H16) -> 0
B17: 001.01.03.01 | C17: 4 | D17: LOCAÇÃO DE EQUIPAMENTOS E MÁQUINA | E17: OE | F17: 1 | G17: 2400 | H17: 2400 | I17: =SUMIF(Lançamentos!$F$7:$F$200,B17&"*",Lançamentos!$O$7:$O$200) -> 0 | J17: =H17-I17 -> 2400 | K17: =IF(H17=0,0,I17/H17) -> 0
B18: 001.01.04 | C18: 3 | D18: ELABORAÇÃO DE PROJETOS | H18: =SUMIFS($H$8:$H$98,$B$8:$B$98,B18&"*",$C$8:$C$98,4) -> 2000 | I18: =SUMIF(Lançamentos!$F$7:$F$200,B18&"*",Lançamentos!$O$7:$O$200) -> 0 | J18: =H18-I18 -> 2000 | K18: =IF(H18=0,0,I18/H18) -> 0
B19: 001.01.04.01 | C19: 4 | D19: CUSTOS COM ELABORAÇÃO DE PROJETOS COMPLEMENTARES | E19: VB | F19: 1 | G19: 2000 | H19: 2000 | I19: =SUMIF(Lançamentos!$F$7:$F$200,B19&"*",Lançamentos!$O$7:$O$200) -> 0 | J19: =H19-I19 -> 2000 | K19: =IF(H19=0,0,I19/H19) -> 0
B20: 001.02 | C20: 2 | D20: SERVIÇOS PRELIMINARES | H20: =SUMIFS($H$8:$H$98,$B$8:$B$98,B20&"*",$C$8:$C$98,4) -> 8695.5596 | I20: =SUMIF(Lançamentos!$F$7:$F$200,B20&"*",Lançamentos!$O$7:$O$200) -> 0 | J20: =H20-I20 -> 8695.5596 | K20: =IF(H20=0,0,I20/H20) -> 0
B21: 001.02.01 | C21: 3 | D21: SERVIÇOS PRELIMINARES | H21: =SUMIFS($H$8:$H$98,$B$8:$B$98,B21&"*",$C$8:$C$98,4) -> 8695.5596 | I21: =SUMIF(Lançamentos!$F$7:$F$200,B21&"*",Lançamentos!$O$7:$O$200) -> 0 | J21: =H21-I21 -> 8695.5596 | K21: =IF(H21=0,0,I21/H21) -> 0
B22: 001.02.01.01 | C22: 4 | D22: DEMOLIÇÃO E TRANSPORTE DE PISO CERÂMICO SOBRE CONTRAPISO | E22: M2 | F22: 39.4259 | G22: 71.44632 | H22: 2816.8355 | I22: =SUMIF(Lançamentos!$F$7:$F$200,B22&"*",Lançamentos!$O$7:$O$200) -> 0 | J22: =H22-I22 -> 2816.8355 | K22: =IF(H22=0,0,I22/H22) -> 0
B23: 001.02.01.02 | C23: 4 | D23: EXECUÇÃO DE LIXAMENTO E LIMPEZA DE CONTRAPISO AUTONIVELANTE | E23: M2 | F23: 39.4259 | G23: 1.9848528 | H23: 78.254608 | I23: =SUMIF(Lançamentos!$F$7:$F$200,B23&"*",Lançamentos!$O$7:$O$200) -> 0 | J23: =H23-I23 -> 78.254608 | K23: =IF(H23=0,0,I23/H23) -> 0
B24: 001.02.01.03 | C24: 4 | D24: DEMOLIÇÃO E TRANSPORTE DE FORRO DE GESSO ALT. ATÉ 3,00M | E24: M2 | F24: 39.4259 | G24: 49.16736 | H24: 1938.4674 | I24: =SUMIF(Lançamentos!$F$7:$F$200,B24&"*",Lançamentos!$O$7:$O$200) -> 0 | J24: =H24-I24 -> 1938.4674 | K24: =IF(H24=0,0,I24/H24) -> 0
B25: 001.02.01.04 | C25: 4 | D25: REMOÇÃO DE BANCADAS | E25: M2 | F25: 5 | G25: 44.55792 | H25: 222.7896 | I25: =SUMIF(Lançamentos!$F$7:$F$200,B25&"*",Lançamentos!$O$7:$O$200) -> 0 | J25: =H25-I25 -> 222.7896 | K25: =IF(H25=0,0,I25/H25) -> 0
B26: 001.02.01.05 | C26: 4 | D26: REMOÇÃO DE RESÍDUOS | E26: M3 | F26: 18 | G26: 122.5 | H26: 2205 | I26: =SUMIF(Lançamentos!$F$7:$F$200,B26&"*",Lançamentos!$O$7:$O$200) -> 0 | J26: =H26-I26 -> 2205 | K26: =IF(H26=0,0,I26/H26) -> 0
B27: 001.02.01.06 | C27: 4 | D27: PROTEÇÃO DE PISO COM SALVA PISO | E27: M2 | F27: 93.0659 | G27: 15.41072 | H27: 1434.2125 | I27: =SUMIF(Lançamentos!$F$7:$F$200,B27&"*",Lançamentos!$O$7:$O$200) -> 0 | J27: =H27-I27 -> 1434.2125 | K27: =IF(H27=0,0,I27/H27) -> 0
B28: 001.03 | C28: 2 | D28: PAREDES E PAINEIS | H28: =SUMIFS($H$8:$H$98,$B$8:$B$98,B28&"*",$C$8:$C$98,4) -> 10849 | I28: =SUMIF(Lançamentos!$F$7:$F$200,B28&"*",Lançamentos!$O$7:$O$200) -> 0 | J28: =H28-I28 -> 10849 | K28: =IF(H28=0,0,I28/H28) -> 0
B29: 001.03.01 | C29: 3 | D29: DIVISÓRIA DE GESSO | H29: =SUMIFS($H$8:$H$98,$B$8:$B$98,B29&"*",$C$8:$C$98,4) -> 10849 | I29: =SUMIF(Lançamentos!$F$7:$F$200,B29&"*",Lançamentos!$O$7:$O$200) -> 0 | J29: =H29-I29 -> 10849 | K29: =IF(H29=0,0,I29/H29) -> 0
B30: 001.03.01.01 | C30: 4 | D30: FORNECIMENTO E EXECUÇÃO DE DRYWALL E LÃ DE VIDRO - TERCEIRIZADO | E30: M2 | F30: 39.6462 | G30: 160.14145 | H30: 6349 | I30: =SUMIF(Lançamentos!$F$7:$F$200,B30&"*",Lançamentos!$O$7:$O$200) -> 0 | J30: =H30-I30 -> 6349 | K30: =IF(H30=0,0,I30/H30) -> 0
B31: 001.03.01.02 | C31: 4 | D31: FORNECIMENTO E EXECUÇÃO DE ELEMENTOS DECORATIVOS EM GESSO | E31: VB | F31: 1 | G31: 4500 | H31: 4500 | I31: =SUMIF(Lançamentos!$F$7:$F$200,B31&"*",Lançamentos!$O$7:$O$200) -> 0 | J31: =H31-I31 -> 4500 | K31: =IF(H31=0,0,I31/H31) -> 0
B32: 001.04 | C32: 2 | D32: FORRO DE GESSO | H32: =SUMIFS($H$8:$H$98,$B$8:$B$98,B32&"*",$C$8:$C$98,4) -> 3420 | I32: =SUMIF(Lançamentos!$F$7:$F$200,B32&"*",Lançamentos!$O$7:$O$200) -> 0 | J32: =H32-I32 -> 3420 | K32: =IF(H32=0,0,I32/H32) -> 0
B33: 001.04.01 | C33: 3 | D33: FORRO DE GESSO | H33: =SUMIFS($H$8:$H$98,$B$8:$B$98,B33&"*",$C$8:$C$98,4) -> 3420 | I33: =SUMIF(Lançamentos!$F$7:$F$200,B33&"*",Lançamentos!$O$7:$O$200) -> 0 | J33: =H33-I33 -> 3420 | K33: =IF(H33=0,0,I33/H33) -> 0
B34: 001.04.01.01 | C34: 4 | D34: FORNECIMENTO E EXECUÇÃO DE FORRO DE GESSO ACARTONADO FGE | E34: M2 | F34: 37.6582 | G34: 90.816874 | H34: 3420 | I34: =SUMIF(Lançamentos!$F$7:$F$200,B34&"*",Lançamentos!$O$7:$O$200) -> 0 | J34: =H34-I34 -> 3420 | K34: =IF(H34=0,0,I34/H34) -> 0
B35: 001.05 | C35: 2 | D35: ESQUADRIAS | H35: =SUMIFS($H$8:$H$98,$B$8:$B$98,B35&"*",$C$8:$C$98,4) -> 6470 | I35: =SUMIF(Lançamentos!$F$7:$F$200,B35&"*",Lançamentos!$O$7:$O$200) -> 0 | J35: =H35-I35 -> 6470 | K35: =IF(H35=0,0,I35/H35) -> 0
B36: 001.05.01 | C36: 3 | D36: ESQUADRIAS DE ALUMÍNIO E VIDRO | H36: =SUMIFS($H$8:$H$98,$B$8:$B$98,B36&"*",$C$8:$C$98,4) -> 720 | I36: =SUMIF(Lançamentos!$F$7:$F$200,B36&"*",Lançamentos!$O$7:$O$200) -> 0 | J36: =H36-I36 -> 720 | K36: =IF(H36=0,0,I36/H36) -> 0
B37: 001.05.01.01 | C37: 4 | D37: FORNECIMENTO E MONTAGEM DE ESQUADRIA FIXA | E37: M2 | F37: 0.9 | G37: 800 | H37: 720 | I37: =SUMIF(Lançamentos!$F$7:$F$200,B37&"*",Lançamentos!$O$7:$O$200) -> 0 | J37: =H37-I37 -> 720 | K37: =IF(H37=0,0,I37/H37) -> 0
B38: 001.05.02 | C38: 3 | D38: ESQUADRIAS DE MADEIRA | H38: =SUMIFS($H$8:$H$98,$B$8:$B$98,B38&"*",$C$8:$C$98,4) -> 5750 | I38: =SUMIF(Lançamentos!$F$7:$F$200,B38&"*",Lançamentos!$O$7:$O$200) -> 0 | J38: =H38-I38 -> 5750 | K38: =IF(H38=0,0,I38/H38) -> 0
B39: 001.05.02.01 | C39: 4 | D39: FORNECIMENTO E MONTAGEM DE PORTA DE MADEIRA 70X210 (PARANÁ) - INCLUSO FERRAGENS (ABRIR) | E39: UND | F39: 3 | G39: 1150 | H39: 3450 | I39: =SUMIF(Lançamentos!$F$7:$F$200,B39&"*",Lançamentos!$O$7:$O$200) -> 0 | J39: =H39-I39 -> 3450 | K39: =IF(H39=0,0,I39/H39) -> 0
B40: 001.05.02.02 | C40: 4 | D40: FORNECIMENTO E MONTAGEM DE PORTA DE MADEIRA 60X210 (PARANÁ) - INCLUSO FERRAGENS (CORRER) | E40: UND | F40: 2 | G40: 1150 | H40: 2300 | I40: =SUMIF(Lançamentos!$F$7:$F$200,B40&"*",Lançamentos!$O$7:$O$200) -> 0 | J40: =H40-I40 -> 2300 | K40: =IF(H40=0,0,I40/H40) -> 0
B41: 001.06 | C41: 2 | D41: REVESTIMENTOS | H41: =SUMIFS($H$8:$H$98,$B$8:$B$98,B41&"*",$C$8:$C$98,4) -> 24342.736 | I41: =SUMIF(Lançamentos!$F$7:$F$200,B41&"*",Lançamentos!$O$7:$O$200) -> 2660.36 | J41: =H41-I41 -> 21682.376 | K41: =IF(H41=0,0,I41/H41) -> 0.10928763
B42: 001.06.01 | C42: 3 | D42: REVESTIMENTO DE PISO | H42: =SUMIFS($H$8:$H$98,$B$8:$B$98,B42&"*",$C$8:$C$98,4) -> 14550.92 | I42: =SUMIF(Lançamentos!$F$7:$F$200,B42&"*",Lançamentos!$O$7:$O$200) -> 2660.36 | J42: =H42-I42 -> 11890.56 | K42: =IF(H42=0,0,I42/H42) -> 0.18283105
B43: 001.06.01.01 | C43: 4 | D43: ASSENTAMENTO DE PORCELANATO 120X120CM COM AC-III E NIVELADORES - PISO | E43: M2 | F43: 39.4259 | G43: 121.81332 | H43: 4802.5998 | I43: =SUMIF(Lançamentos!$F$7:$F$200,B43&"*",Lançamentos!$O$7:$O$200) -> 0 | J43: =H43-I43 -> 4802.5998 | K43: =IF(H43=0,0,I43/H43) -> 0
...

Sheet Lançamentos
B2: Controle Financeiro · Lançamentos
B3: Cada lançamento é vinculado a um código da EAP do orçamento (coluna F) para o comparativo Orçado x Realizado
B4: Legenda: fundo amarelo claro = preenchimento manual do vínculo com o orçamento. Coluna G é automática (item da EAP).
B6: Nº | C6: Data e hora | D6: Projeto | E6: Centro de custo | F6: Código EAP | G6: Item do orçamento (EAP) | H6: Descrição | I6: Favorecido | J6: Instituição (destino) | K6: Tipo | L6: Pagador (origem) | M6: Instituição (origem) | N6: ID da transação | O6: Valor (R$) | P6: Anexo | Q6: Observação
B7: 1 | C7: 46288.443 | D7: Clínica Sensi | E7: Instalações Frigorígenas | F7: 001.09.04.01 | G7: =IFERROR(INDEX('Orçado x Realizado'!$D$8:$D$200,MATCH(F7,'Orçado x Realizado'!$B$8:$B$200,0)),"código não encontrado") -> FORNECIMENTO E EXECUÇÃO DE INSTALAÇÃO FRIGORÍGENA | H7: Aquisição de tubos e conexões em cobre, esponjosos e itens elétricos | I7: Alexandre Araujo da Silva | J7: Caixa Econômica Federal | K7: Pix | L7: Vitoria Brenda Borges Aquino | M7: Nubank (NU Pagamentos - IP) | N7: E18236120202609231338s104aa8169c | O7: 4411.16 | P7: Ver anexo | Q7: Vínculo assumido: item 001.09.04.01 (Instalação frigorígena). Parte da compra são itens elétricos — confirmar se deve ser rateada com 001.09.01.01.
B8: 2 | C8: 46286.702 | D8: Clínica Sensi | E8: Revestimento Cerâmico | F8: 001.06.01.02 | G8: =IFERROR(INDEX('Orçado x Realizado'!$D$8:$D$200,MATCH(F8,'Orçado x Realizado'!$B$8:$B$200,0)),"código não encontrado") -> FORNECIMENTO PORCELANATO PORTOBELLO 90X90CM AETERNA BIANCO | H8: Pagamento à Cerâmica Cerbras (revestimento cerâmico) | I8: Cerâmica Cerbras | J8: Banco Santander (Brasil) S.A. | K8: Pix | L8: Sabrina Amabili Educação LTDA | M8: Nubank (NU Pagamentos - IP) | N8: E18236120202609211951s12412875f4 | O8: 2660.36 | P8: Ver anexo | Q8: Vínculo assumido: fornecimento de porcelanato de PISO (001.06.01.02); se for parede, usar 001.06.02.03.
B201: TOTAL | O201: =SUM(O7:O200) -> 7071.52

Sheet Anexos
B2: Anexos · Comprovantes
B3: Numeração igual à coluna Nº da aba Lançamentos
B5: 01 · Alexandre Araujo da Silva · R$ 4.411,16 | C5: 02 · Cerâmica Cerbras · R$ 2.660,36
B6: Instalações Frigorígenas · 23/09/2026 | C6: Revestimento Cerâmico · 21/09/2026
